Workbook

Sheet Form responses 2
A1: Timestamp | B1: Who are you? | C1: What's your PIN? | D1: Who'll win the Golden Boot? The Golden Boot is awarded to the player with the most goals during the tournament. Should there be a shared boot at the end of the tournament, you'll score 5 points for any of the players sharing the boot. | E1: Who'll win the Golden Ball? The Golden Ball is awarded to the player voted as the best player of the tournament. | F1: Who'll win the Golden Glove? The Golden Glove is awarded to the player voted as the best goalkeeper of the tournament. | G1: Who'll win the Best Young Player award? The Best Young Player award is awarded to a player who is under 21 at the start of the calendar year. | H1: Group A | I1: Group B | J1: Group C | K1: Group D | L1: Group E | M1: Group F | N1: Group G | O1: Group H | P1: Which team will win the FIFA Fair Play Trophy? The FIFA Fair Play Trophy is given to the team with the best record of fair play. | Q1: Which team will win the Most Entertaining Team award? As voted for by a public opinion poll run by FIFA. | R1: Which team will be the first finalist? 5 points for any team that reaches the final. | S1: Which team will be the second finalist? 5 points for any team that reaches the final. | T1: Which country will be the 2022 FIFA World Cup Champions? | U1: Email address
A2: 44877.687 | B2: Donovan | C2: 2279 | D2: Mbape | E2: Lewondowski | F2: Alisson | G2: Jude Bellingham | H2: Senegal, Netherlands | I2: England, USA | J2: Argentina, Mexico | K2: France, Denmark | L2: Spain, Germany | M2: Belgium, Croatia | N2: Brazil, Cameroon | O2: Portugal, Uruguay | P2: Japan | Q2: Brazil | R2: Brazil | S2: France | T2: Germany
A3: 44879.216 | B3: Anthony | C3: 2269 | D3: Karim Benzema | E3: Vincius Junior | F3: Alisson Becker | G3: Jamal Musiala | H3: Ecuador, Netherlands | I3: England, USA | J3: Argentina, Mexico | K3: France, Denmark | L3: Spain, Germany | M3: Belgium, Morocco | N3: Brazil, Serbia | O3: Portugal, Uruguay | P3: Mexico | Q3: Ghana | R3: Uruguay | S3: Spain | T3: Brazil
A4: 44880.423 | B4: Selwyn | C4: 5589 | D4: Lionel Messi | E4: Lionel Messi | F4: Thibaut Courtois | G4: Pedri | H4: Senegal, Netherlands | I4: England, Wales | J4: Argentina, Poland | K4: France, Denmark | L4: Spain, Germany | M4: Belgium, Croatia | N4: Brazil, Serbia | O4: Portugal, Uruguay | P4: Denmark | Q4: Brazil | R4: Brazil | S4: France | T4: Portugal
A5: 44881.677 | B5: Donovan | C5: 2279 | D5: Vinicius Jr | E5: Bernardo Silva | F5: Alisson Becker | G5: Jude Bellingham | H5: Senegal, Netherlands | I5: England, USA | J5: Argentina, Poland | K5: France, Denmark | L5: Spain, Germany | M5: Belgium, Croatia | N5: Brazil, Cameroon | O5: Portugal, Uruguay | P5: Japan | Q5: Brazil | R5: England | S5: France | T5: Brazil
A6: 44882.648 | B6: Sonia | C6: 8934 | D6: Gabriel Jesus | E6: Neymar | F6: Diogo Costa | G6: Vitinha | H6: Senegal, Netherlands | I6: England, IR Iran | J6: Argentina, Poland | K6: France, Denmark | L6: Spain, Germany | M6: Belgium, Croatia | N6: Brazil, Serbia | O6: Portugal, Uruguay | P6: Denmark | Q6: Brazil | R6: Brazil | S6: France | T6: Brazil
A7: 44884.554 | B7: Sonia | C7: 8934 | D7: Gabriel Jesus | E7: Joao Felix | F7: Diogo Costa | G7: Ansu Fati | H7: Senegal, Netherlands | I7: England, IR Iran | J7: Argentina, Poland | K7: France, Denmark | L7: Spain, Germany | M7: Belgium, Croatia | N7: Brazil, Serbia | O7: Portugal, Uruguay | P7: Denmark | Q7: Brazil | R7: Portugal | S7: Brazil | T7: Portugal
A8: 44884.695 | B8: Martin | C8: 2648 | D8: Kylian Mbappé | E8: Cristiano Ronaldo | F8: Diogo Costa | G8: Nuno Mendes | H8: Ecuador, Netherlands | I8: England, Wales | J8: Argentina, Poland | K8: France, Denmark | L8: Spain, Germany | M8: Belgium, Croatia | N8: Brazil, Switzerland | O8: Portugal, Ghana | P8: Denmark | Q8: Brazil | R8: Portugal | S8: Argentina | T8: Portugal
A9: 44885.57 | B9: Paulo | C9: 6025 | D9: Mbappe | E9: Neymar | F9: Diogo Costa | G9: Jude Bellingham | H9: Ecuador, Netherlands | I9: England, Wales | J9: Argentina, Poland | K9: France, Denmark | L9: Spain, Germany | M9: Belgium, Croatia | N9: Brazil, Serbia | O9: Portugal, Uruguay | P9: Japan | Q9: Netherlands | R9: Brazil | S9: France | T9: Brazil
A10: 44885.607 | B10: Ago | C10: 7803 | D10: Kylian Mbappe | E10: Lionel Messi | F10: Emiliano Martinez | G10: Gavi | H10: Qatar, Netherlands | I10: England, Wales | J10: Argentina, Mexico | K10: France, Denmark | L10: Spain, Germany | M10: Belgium, Croatia | N10: Brazil, Cameroon | O10: Portugal, Uruguay | P10: Denmark | Q10: Spain | R10: France | S10: Argentina | T10: Portugal

Sheet Predictions
D1: Martin | G1: Ago | J1: Sonia | M1: Anthony | P1: Paulo | S1: Selwyn | V1: Donovan
C2: Result | D2: Prediction | E2: Score | G2: Prediction | H2: Score | J2: Prediction | K2: Score | M2: Prediction | N2: Score | P2: Prediction | Q2: Score | S2: Prediction | T2: Score | V2: Prediction | W2: Score
A3: Golden Boot | C3: Kylian Mbappe | D3: Kylian Mbappé | E3: 5 | G3: Kylian Mbappe | H3: 5 | J3: Gabriel Jesus | K3: 0 | M3: Lautaro Martinez | N3: 0 | P3: Mbappe | Q3: 5 | S3: Lionel Messi | T3: 0 | V3: Vinicius Jr | W3: 0
A4: Golden Ball | C4: Lionel Messi | D4: Cristiano Ronaldo | E4: 0 | G4: Lionel Messi | H4: 5 | J4: Joao Felix | K4: 0 | M4: Vincius Junior | N4: 0 | P4: Neymar | Q4: 0 | S4: Lionel Messi | T4: 5 | V4: Bernardo Silva | W4: 0
A5: Golden Glove | C5: Emiliano Martinez | D5: Diogo Costa | E5: 0 | G5: Emiliano Martinez | H5: 5 | J5: Diogo Costa | K5: 0 | M5: Alisson Becker | N5: 0 | P5: Diogo Costa | Q5: 0 | S5: Thibaut Courtois | T5: 0 | V5: Alisson Becker | W5: 0
A6: Best Young Player | C6: Enzo Fernandez | D6: Nuno Mendes | E6: 0 | G6: Gavi | H6: 0 | J6: Ansu Fati | K6: 0 | M6: Jamal Musiala | N6: 0 | P6: Jude Bellingham | Q6: 0 | S6: Pedri | T6: 0 | V6: Jude Bellingham | W6: 0
A7: Group A | C7: Netherlands, Senegal | D7: Ecuador, Netherlands | E7: 2 | G7: Qatar, Netherlands | H7: 2 | J7: Senegal, Netherlands | K7: 4 | M7: Ecuador, Netherlands | N7: 2 | P7: Ecuador, Netherlands | Q7: 2 | S7: Senegal, Netherlands | T7: 4 | V7: Senegal, Netherlands | W7: 4
A8: Group B | C8: England, USA | D8: England, Wales | E8: 2 | G8: England, Wales | H8: 2 | J8: England, IR Iran | K8: 2 | M8: England, USA | N8: 4 | P8: England, Wales | Q8: 2 | S8: England, Wales | T8: 2 | V8: England, USA | W8: 4
A9: Group C | C9: Argentina, Poland | D9: Argentina, Poland | E9: 4 | G9: Argentina, Mexico | H9: 2 | J9: Argentina, Poland | K9: 4 | M9: Argentina, Mexico | N9: 2 | P9: Argentina, Poland | Q9: 4 | S9: Argentina, Poland | T9: 4 | V9: Argentina, Poland | W9: 4
A10: Group D | C10: France, Australia | D10: France, Denmark | E10: 2 | G10: France, Denmark | H10: 2 | J10: France, Denmark | K10: 2 | M10: France, Denmark | N10: 2 | P10: France, Denmark | Q10: 2 | S10: France, Denmark | T10: 2 | V10: France, Denmark | W10: 2
A11: Group E | C11: Japan, Spain | D11: Spain, Germany | E11: 2 | G11: Spain, Germany | H11: 2 | J11: Spain, Germany | K11: 2 | M11: Spain, Germany | N11: 2 | P11: Spain, Germany | Q11: 2 | S11: Spain, Germany | T11: 2 | V11: Spain, Germany | W11: 2
A12: Group F | C12: Morocco, Croatia | D12: Belgium, Croatia | E12: 2 | G12: Belgium, Croatia | H12: 2 | J12: Belgium, Croatia | K12: 2 | M12: Belgium, Morocco | N12: 2 | P12: Belgium, Croatia | Q12: 2 | S12: Belgium, Croatia | T12: 2 | V12: Belgium, Croatia | W12: 2
A13: Group G | C13: Brazil, Switzerland | D13: Brazil, Switzerland | E13: 4 | G13: Brazil, Cameroon | H13: 2 | J13: Brazil, Serbia | K13: 2 | M13: Brazil, Serbia | N13: 2 | P13: Brazil, Serbia | Q13: 2 | S13: Brazil, Serbia | T13: 2 | V13: Brazil, Cameroon | W13: 2
A14: Group H | C14: Portugal, Korea Republic | D14: Portugal, Ghana | E14: 2 | G14: Portugal, Uruguay | H14: 2 | J14: Portugal, Uruguay | K14: 2 | M14: Portugal, Uruguay | N14: 2 | P14: Portugal, Uruguay | Q14: 2 | S14: Portugal, Uruguay | T14: 2 | V14: Portugal, Uruguay | W14: 2
A15: Fifa Fair Play | C15: England | D15: Denmark | E15: 0 | G15: Denmark | H15: 0 | J15: Denmark | K15: 0 | M15: Mexico | N15: 0 | P15: Japan | Q15: 0 | S15: Denmark | T15: 0 | V15: Japan | W15: 0
A16: Most Entertaining Team | D16: Brazil | G16: Spain | J16: Brazil | M16: Ghana | P16: Netherlands | S16: Brazil | V16: Brazil
A17: Finalist 1 | C17: Argentina | D17: Portugal | E17: 0 | G17: France | H17: 5 | J17: Portugal | K17: 0 | M17: Uruguay | N17: 0 | P17: Brazil | Q17: 0 | S17: Brazil | T17: 0 | V17: England | W17: 0
A18: Finalist 2 | C18: France | D18: Argentina | E18: 5 | G18: Argentina | H18: 5 | J18: Brazil | K18: 0 | M18: Spain | N18: 0 | P18: France | Q18: 5 | S18: France | T18: 5 | V18: France | W18: 5
A19: Champion | C19: Argentina | D19: Portugal | E19: 0 | G19: Portugal | H19: 0 | J19: Portugal | K19: 0 | M19: Brazil | N19: 0 | P19: Brazil | Q19: 0 | S19: Portugal | T19: 0 | V19: Brazil | W19: 0
E20: =SUM(E3:E19) -> 30 | H20: =SUM(H3:H19) -> 41 | K20: =SUM(K3:K19) -> 20 | N20: =SUM(N3:N19) -> 18 | Q20: =SUM(Q3:Q19) -> 28 | T20: =SUM(T3:T19) -> 30 | W20: =SUM(W3:W19) -> 27
A21: Match Points | E21: =Points!O1 -> 33 | H21: =Points!S1 -> 45 | K21: =Points!W1 -> 42.5 | N21: =Points!AA1 -> 41 | Q21: =Points!AE1 -> 38 | T21: =Points!AI1 -> 61.5 | W21: =Points!AM1 -> 44.5
A22: Total | E22: =SUM(E20:E21) -> 63 | H22: =SUM(H20:H21) -> 86 | K22: =SUM(K20:K21) -> 62.5 | N22: =SUM(N20:N21) -> 59 | Q22: =SUM(Q20:Q21) -> 66 | T22: =SUM(T20:T21) -> 91.5 | W22: =SUM(W20:W21) -> 71.5

Sheet Points
A1: Results | M1: Martin | O1: =O19+O36+O53+O62+O67+O70+O73 -> 33 | Q1: Ago | S1: =S19+S36+S53+S62+S67+S70+S73 -> 45 | U1: Sonia | W1: =W19+W36+W53+W62+W67+W70+W73 -> 42.5 | Y1: Anthony | AA1: =AA19+AA36+AA53+AA62+AA67+AA70+AA73 -> 41 | AC1: Paulo | AE1: =AE19+AE36+AE53+AE62+AE67+AE70+AE73 -> 38 | AG1: Selwyn | AI1: =AI19+AI36+AI53+AI62+AI67+AI70+AI73 -> 61.5 | AK1: Donovan | AM1: =AM19+AM36+AM53+AM62+AM67+AM70+AM73 -> 44.5
A2: Match | B2: Round | C2: DOW | D2: Date | E2: Time | G2: Team 1 | H2: S1 | I2: S2 | J2: Team 2 | K2: Penalties | M2: P1 | N2: P2 | O2: Score | Q2: P1 | R2: P2 | S2: Score | U2: P1 | V2: P2 | W2: Score | Y2: P1 | Z2: P2 | AA2: Score | AC2: P1 | AD2: P2 | AE2: Score | AG2: P1 | AH2: P2 | AI2: Score | AK2: P1 | AL2: P2 | AM2: Score
A3: 1 | B3: 1 | C3: Sun | D3: 44885 | E3: 0.79166667 | G3: Qatar | H3: 0 | I3: 2 | J3: Ecuador | M3: 1 | N3: 3 | O3: 2 | P3: 2 | Q3: 1 | R3: 0 | S3: 0 | T3: 0 | U3: 0 | V3: 1 | W3: 1 | X3: 1 | Y3: 2 | Z3: 0 | AA3: 0 | AB3: 0 | AC3: 0 | AD3: 1 | AE3: 1 | AF3: 1 | AG3: 1 | AH3: 0 | AI3: 0 | AJ3: 0 | AK3: 1 | AL3: 1 | AM3: 0 | AN3: 0
A4: 2 | B4: 1 | C4: Mon | D4: 44886 | E4: 0.79166667 | G4: Senegal | H4: 0 | I4: 2 | J4: Netherlands | M4: 1 | N4: 1 | O4: 0 | P4: 2 | Q4: 0 | R4: 3 | S4: 1 | T4: 1 | U4: 1 | V4: 1 | W4: 0 | X4: 1 | Y4: 2 | Z4: 3 | AA4: 1 | AB4: 1 | AC4: 0 | AD4: 2 | AE4: 3 | AF4: 4 | AG4: 1 | AH4: 2 | AI4: 1 | AJ4: 1 | AK4: 1 | AL4: 3 | AM4: 2 | AN4: 2
A5: 3 | B5: 1 | C5: Mon | D5: 44886 | E5: 0.66666667 | G5: England | H5: 6 | I5: 2 | J5: Iran | M5: 1 | N5: 0 | O5: 1 | P5: 3 | Q5: 3 | R5: 0 | S5: 1 | T5: 2 | U5: 3 | V5: 1 | W5: 1 | X5: 2 | Y5: 2 | Z5: 2 | AA5: 0 | AB5: 1 | AC5: 1 | AD5: 0 | AE5: 1 | AF5: 5 | AG5: 3 | AH5: 0 | AI5: 1 | AJ5: 2 | AK5: 4 | AL5: 0 | AM5: 2 | AN5: 4
A6: 4 | B6: 1 | C6: Mon | D6: 44886 | E6: 0.91666667 | G6: United States | H6: 1 | I6: 1 | J6: Wales | M6: 1 | N6: 2 | O6: 0 | P6: 3 | Q6: 0 | R6: 1 | S6: 0 | T6: 2 | U6: 2 | V6: 1 | W6: 0 | X6: 2 | Y6: 3 | Z6: 2 | AA6: 0 | AB6: 1 | AC6: 0 | AD6: 1 | AE6: 0 | AF6: 5 | AG6: 1 | AH6: 2 | AI6: 0 | AJ6: 2 | AK6: 2 | AL6: 1 | AM6: 0 | AN6: 4
A7: 5 | B7: 1 | C7: Tue | D7: 44887 | E7: 0.54166667 | G7: Argentina | H7: 1 | I7: 2 | J7: Saudi Arabia | M7: 5 | N7: 0 | O7: 0 | P7: 3 | Q7: 4 | R7: 0 | S7: 0 | T7: 2 | U7: 5 | V7: 0 | W7: 0 | X7: 2 | Y7: 3 | Z7: 0 | AA7: 0 | AB7: 1 | AC7: 5 | AD7: 0 | AE7: 0 | AF7: 5 | AG7: 4 | AH7: 0 | AI7: 0 | AJ7: 2 | AK7: 2 | AL7: 0 | AM7: 0 | AN7: 4
A8: 6 | B8: 1 | C8: Tue | D8: 44887 | E8: 0.66666667 | G8: Denmark | H8: 0 | I8: 0 | J8: Tunisia | M8: 2 | N8: 0 | O8: 0 | P8: 3 | Q8: 2 | R8: 1 | S8: 0 | T8: 2 | U8: 1 | V8: 0 | W8: 0 | X8: 2 | Y8: 2 | Z8: 1 | AA8: 0 | AB8: 1 | AC8: 3 | AD8: 0 | AE8: 0 | AF8: 5 | AG8: 2 | AH8: 1 | AI8: 0 | AJ8: 2 | AK8: 2 | AL8: 0 | AM8: 0 | AN8: 4
A9: 7 | B9: 1 | C9: Tue | D9: 44887 | E9: 0.79166667 | G9: Mexico | H9: 0 | I9: 0 | J9: Poland | M9: 1 | N9: 1 | O9: 1.5 | P9: 4.5 | Q9: 1 | R9: 0 | S9: 0 | T9: 2 | U9: 2 | V9: 2 | W9: 1.5 | X9: 3.5 | Y9: 3 | Z9: 1 | AA9: 0 | AB9: 1 | AC9: 1 | AD9: 2 | AE9: 0 | AF9: 5 | AG9: 2 | AH9: 2 | AI9: 1.5 | AJ9: 3.5 | AK9: 1 | AL9: 2 | AM9: 0 | AN9: 4
A10: 8 | B10: 1 | C10: Tue | D10: 44887 | E10: 0.91666667 | G10: France | H10: 4 | I10: 1 | J10: Australia | M10: 3 | N10: 1 | O10: 1 | P10: 5.5 | Q10: 4 | R10: 0 | S10: 1 | T10: 3 | U10: 6 | V10: 0 | W10: 1 | X10: 4.5 | Y10: 3 | Z10: 1 | AA10: 1 | AB10: 2 | AC10: 3 | AD10: 0 | AE10: 2 | AF10: 7 | AG10: 4 | AH10: 0 | AI10: 1 | AJ10: 4.5 | AK10: 3 | AL10: 1 | AM10: 1 | AN10: 5
A11: 9 | B11: 1 | C11: Wed | D11: 44888 | E11: 0.54166667 | G11: Morocco | H11: 0 | I11: 0 | J11: Croatia | M11: 1 | N11: 1 | O11: 1.5 | P11: 7 | Q11: 0 | R11: 2 | S11: 0 | T11: 3 | U11: 1 | V11: 3 | W11: 0 | X11: 4.5 | Y11: 2 | Z11: 1 | AA11: 0 | AB11: 2 | AC11: 1 | AD11: 2 | AE11: 0 | AF11: 7 | AG11: 1 | AH11: 2 | AI11: 0 | AJ11: 4.5 | AK11: 0 | AL11: 3 | AM11: 0 | AN11: 5
A12: 10 | B12: 1 | C12: Wed | D12: 44888 | E12: 0.66666667 | G12: Germany | H12: 1 | I12: 2 | J12: Japan | M12: 4 | N12: 1 | O12: 0 | P12: 7 | Q12: 3 | R12: 0 | S12: 0 | T12: 3 | U12: 4 | V12: 1 | W12: 0 | X12: 4.5 | Y12: 3 | Z12: 0 | AA12: 0 | AB12: 2 | AC12: 3 | AD12: 2 | AE12: 0 | AF12: 7 | AG12: 2 | AH12: 0 | AI12: 0 | AJ12: 4.5 | AK12: 3 | AL12: 1 | AM12: 0 | AN12: 5
A13: 11 | B13: 1 | C13: Wed | D13: 44888 | E13: 0.79166667 | G13: Spain | H13: 7 | I13: 0 | J13: Costa Rica | M13: 3 | N13: 0 | O13: 1 | P13: 8 | Q13: 2 | R13: 0 | S13: 1 | T13: 4 | U13: 3 | V13: 0 | W13: 1 | X13: 5.5 | Y13: 2 | Z13: 1 | AA13: 1 | AB13: 3 | AC13: 2 | AD13: 0 | AE13: 1 | AF13: 8 | AG13: 2 | AH13: 1 | AI13: 1 | AJ13: 5.5 | AK13: 2 | AL13: 0 | AM13: 1 | AN13: 6
A14: 12 | B14: 1 | C14: Wed | D14: 44888 | E14: 0.91666667 | G14: Belgium | H14: 1 | I14: 0 | J14: Canada | M14: 2 | N14: 0 | O14: 1 | P14: 9 | Q14: 5 | R14: 0 | S14: 1 | T14: 5 | U14: 4 | V14: 0 | W14: 1 | X14: 6.5 | Y14: 2 | Z14: 0 | AA14: 1 | AB14: 4 | AC14: 3 | AD14: 1 | AE14: 1 | AF14: 9 | AG14: 4 | AH14: 0 | AI14: 1 | AJ14: 6.5 | AK14: 3 | AL14: 0 | AM14: 1 | AN14: 7
... A18: 16 | B18: 1 | C18: Thu | D18: 44889 | E18: 0.91666667 | G18: Brazil | H18: 2 | I18: 0 | J18: Serbia | M18: 0 | N18: 1 | O18: 0 | P18: 11 | Q18: 2 | R18: 0 | S18: 3 | T18: 9 | U18: 2 | V18: 1 | W18: 1 | X18: 11.5 | Y18: 2 | Z18: 1 | AA18: 1 | AB18: 8 | AC18: 1 | AD18: 0 | AE18: 1 | AF18: 12 | AG18: 2 | AH18: 1 | AI18: 1 | AJ18: 10.5 | AK18: 2 | AL18: 1 | AM18: 1 | AN18: 9
O19: 11 | P19: 11 | S19: 9 | T19: 9 | W19: 11.5 | X19: 11.5 | AA19: 8 | AB19: 8 | AE19: 12 | AF19: 12 | AI19: 10.5 | AJ19: 10.5 | AM19: 9 | AN19: 9
A20: 17 | B20: 2 | C20: Fri | D20: 44890 | E20: 0.54166667 | G20: Wales | H20: 0 | I20: 2 | J20: Iran | M20: 0 | N20: 1 | O20: 1 | P20: 12 | Q20: 2 | R20: 2 | S20: 0 | T20: 9 | U20: 2 | V20: 2 | W20: 0 | X20: 11.5 | Y20: 2 | Z20: 2 | AA20: 0 | AB20: 8 | AC20: 2 | AD20: 1 | AE20: 0 | AF20: 12 | AG20: 2 | AH20: 1 | AI20: 0 | AJ20: 10.5 | AK20: 3 | AL20: 0 | AM20: 0 | AN20: 9
A21: 18 | B21: 2 | C21: Fri | D21: 44890 | E21: 0.66666667 | G21: Qatar | H21: 1 | I21: 3 | J21: Senegal | M21: 0 | N21: 2 | O21: 2 | P21: 14 | Q21: 0 | R21: 1 | S21: 1 | T21: 10 | U21: 0 | V21: 2 | W21: 2 | X21: 13.5 | Y21: 1 | Z21: 2 | AA21: 1 | AB21: 9 | AC21: 0 | AD21: 2 | AE21: 2 | AF21: 14 | AG21: 1 | AH21: 2 | AI21: 1 | AJ21: 11.5 | AK21: 0 | AL21: 3 | AM21: 1 | AN21: 10
A22: 19 | B22: 2 | C22: Fri | D22: 44890 | E22: 0.79166667 | G22: Netherlands | H22: 1 | I22: 1 | J22: Ecuador | M22: 2 | N22: 0 | O22: 0 | P22: 14 | Q22: 2 | R22: 1 | S22: 0 | T22: 10 | U22: 3 | V22: 2 | W22: 0 | X22: 13.5 | Y22: 3 | Z22: 1 | AA22: 0 | AB22: 9 | AC22: 2 | AD22: 1 | AE22: 0 | AF22: 14 | AG22: 1 | AH22: 1 | AI22: 3 | AJ22: 14.5 | AK22: 2 | AL22: 1 | AM22: 0 | AN22: 10
A23: 20 | B23: 2 | C23: Fri | D23: 44890 | E23: 0.91666667 | G23: England | H23: 0 | I23: 0 | J23: United States | M23: 3 | N23: 0 | O23: 0 | P23: 14 | Q23: 3 | R23: 1 | S23: 0 | T23: 10 | U23: 3 | V23: 1 | W23: 0 | X23: 13.5 | Y23: 1 | Z23: 1 | AA23: 1.5 | AB23: 10.5 | AC23: 2 | AD23: 0 | AE23: 0 | AF23: 14 | AG23: 1 | AH23: 0 | AI23: 0 | AJ23: 14.5 | AK23: 2 | AL23: 1 | AM23: 0 | AN23: 10
A24: 21 | B24: 2 | C24: Sat | D24: 44891 | E24: 0.54166667 | G24: Tunisia | H24: 0 | I24: 1 | J24: Australia | M24: 2 | N24: 1 | O24: 0 | P24: 14 | Q24: 1 | R24: 1 | S24: 0 | T24: 10 | U24: 1 | V24: 0 | W24: 0 | X24: 13.5 | Y24: 2 | Z24: 1 | AA24: 0 | AB24: 10.5 | AC24: 1 | AD24: 0 | AE24: 0 | AF24: 14 | AG24: 2 | AH24: 2 | AI24: 0 | AJ24: 14.5 | AK24: 1 | AL24: 1 | AM24: 0 | AN24: 10
A25: 22 | B25: 2 | C25: Sat | D25: 44891 | E25: 0.66666667 | G25: Poland | H25: 2 | I25: 0 | J25: Saudi Arabia | M25: 3 | N25: 0 | O25: 1 | P25: 15 | Q25: 1 | R25: 0 | S25: 1 | T25: 11 | U25: 2 | V25: 1 | W25: 1 | X25: 14.5 | Y25: 2 | Z25: 1 | AA25: 1 | AB25: 11.5 | AC25: 2 | AD25: 1 | AE25: 1 | AF25: 15 | AG25: 3 | AH25: 0 | AI25: 1 | AJ25: 15.5 | AK25: 2 | AL25: 1 | AM25: 1 | AN25: 11
A26: 23 | B26: 2 | C26: Sat | D26: 44891 | E26: 0.79166667 | G26: France | H26: 2 | I26: 1 | J26: Denmark | M26: 1 | N26: 1 | O26: 0 | P26: 15 | Q26: 2 | R26: 0 | S26: 1 | T26: 12 | U26: 3 | V26: 0 | W26: 1 | X26: 15.5 | Y26: 1 | Z26: 1 | AA26: 0 | AB26: 11.5 | AC26: 2 | AD26: 1 | AE26: 3 | AF26: 18 | AG26: 1 | AH26: 0 | AI26: 2 | AJ26: 17.5 | AK26: 3 | AL26: 1 | AM26: 1 | AN26: 12
A27: 24 | B27: 2 | C27: Sat | D27: 44891 | E27: 0.91666667 | G27: Argentina | H27: 0 | I27: 0 | J27: Mexico | M27: 1 | N27: 1 | O27: 1.5 | P27: 16.5 | Q27: 2 | R27: 1 | S27: 0 | T27: 12 | U27: 2 | V27: 0 | W27: 0 | X27: 15.5 | Y27: 2 | Z27: 1 | AA27: 0 | AB27: 11.5 | AC27: 2 | AD27: 1 | AE27: 0 | AF27: 18 | AG27: 2 | AH27: 1 | AI27: 0 | AJ27: 17.5 | AK27: 1 | AL27: 1 | AM27: 1.5 | AN27: 13.5
A28: 25 | B28: 2 | C28: Sun | D28: 44892 | E28: 0.54166667 | G28: Japan | H28: 0 | I28: 1 | J28: Costa Rica | M28: 3 | N28: 0 | O28: 0 | P28: 16.5 | Q28: 2 | R28: 0 | S28: 0 | T28: 12 | U28: 1 | V28: 0 | W28: 0 | X28: 15.5 | Y28: 0 | Z28: 2 | AA28: 1 | AB28: 12.5 | AC28: 3 | AD28: 0 | AE28: 0 | AF28: 18 | AG28: 2 | AH28: 1 | AI28: 0 | AJ28: 17.5 | AK28: 2 | AL28: 0 | AM28: 0 | AN28: 13.5
A29: 26 | B29: 2 | C29: Sun | D29: 44892 | E29: 0.66666667 | G29: Belgium | H29: 0 | I29: 2 | J29: Morocco | M29: 1 | N29: 1 | O29: 0 | P29: 16.5 | Q29: 1 | R29: 0 | S29: 0 | T29: 12 | U29: 2 | V29: 0 | W29: 0 | X29: 15.5 | Y29: 2 | Z29: 2 | AA29: 0 | AB29: 12.5 | AC29: 1 | AD29: 0 | AE29: 0 | AF29: 18 | AG29: 1 | AH29: 0 | AI29: 0 | AJ29: 17.5 | AK29: 2 | AL29: 0 | AM29: 0 | AN29: 13.5
A30: 27 | B30: 2 | C30: Sun | D30: 44892 | E30: 0.79166667 | G30: Croatia | H30: 4 | I30: 1 | J30: Canada | M30: 1 | N30: 0 | O30: 1 | P30: 17.5 | Q30: 2 | R30: 0 | S30: 1 | T30: 13 | U30: 1 | V30: 0 | W30: 1 | X30: 16.5 | Y30: 3 | Z30: 0 | AA30: 2 | AB30: 14.5 | AC30: 1 | AD30: 0 | AE30: 1 | AF30: 19 | AG30: 1 | AH30: 2 | AI30: 0 | AJ30: 17.5 | AK30: 0 | AL30: 1 | AM30: 0 | AN30: 13.5
A31: 28 | B31: 2 | C31: Sun | D31: 44892 | E31: 0.91666667 | G31: Spain | H31: 1 | I31: 1 | J31: Germany | M31: 2 | N31: 1 | O31: 0 | P31: 17.5 | Q31: 2 | R31: 1 | S31: 0 | T31: 13 | U31: 2 | V31: 1 | W31: 0 | X31: 16.5 | Y31: 2 | Z31: 1 | AA31: 0 | AB31: 14.5 | AC31: 2 | AD31: 1 | AE31: 0 | AF31: 19 | AG31: 3 | AH31: 1 | AI31: 0 | AJ31: 17.5 | AK31: 2 | AL31: 1 | AM31: 0 | AN31: 13.5
... A35: 32 | B35: 2 | C35: Mon | D35: 44893 | E35: 0.91666667 | G35: Portugal | H35: 2 | I35: 0 | J35: Uruguay | M35: 3 | N35: 1 | O35: 2 | P35: 19.5 | Q35: 1 | R35: 0 | S35: 1 | T35: 17 | U35: 3 | V35: 1 | W35: 2 | X35: 19.5 | Y35: 3 | Z35: 1 | AA35: 2 | AB35: 18.5 | AC35: 1 | AD35: 1 | AE35: 0 | AF35: 21 | AG35: 1 | AH35: 1 | AI35: 0 | AJ35: 21 | AK35: 1 | AL35: 1 | AM35: 0 | AN35: 18
O36: 8.5 | P36: 19.5 | S36: 8 | T36: 17 | W36: 8 | X36: 19.5 | AA36: 10.5 | AB36: 18.5 | AE36: 9 | AF36: 21 | AI36: 10.5 | AJ36: 21 | AM36: 9 | AN36: 18
A37: 33 | B37: 3 | C37: Tue | D37: 44894 | E37: 0.75 | G37: Ecuador | H37: 1 | I37: 2 | J37: Senegal | M37: 2 | N37: 1 | O37: 0 | P37: 19.5 | Q37: 2 | R37: 1 | S37: 0 | T37: 17 | U37: 2 | V37: 2 | W37: 0 | X37: 19.5 | Y37: 1 | Z37: 2 | AA37: 3 | AB37: 21.5 | AC37: 2 | AD37: 1 | AE37: 0 | AF37: 21 | AG37: 1 | AH37: 2 | AI37: 3 | AJ37: 24 | AK37: 1 | AL37: 1 | AM37: 0 | AN37: 18
A38: 34 | B38: 3 | C38: Tue | D38: 44894 | E38: 0.75 | G38: Netherlands | H38: 2 | I38: 0 | J38: Qatar | M38: 4 | N38: 0 | O38: 1 | P38: 20.5 | Q38: 3 | R38: 0 | S38: 1 | T38: 18 | U38: 4 | V38: 0 | W38: 1 | X38: 20.5 | Y38: 2 | Z38: 0 | AA38: 3 | AB38: 24.5 | AC38: 3 | AD38: 0 | AE38: 1 | AF38: 22 | AG38: 2 | AH38: 0 | AI38: 3 | AJ38: 27 | AK38: 3 | AL38: 0 | AM38: 1 | AN38: 19
A39: 35 | B39: 3 | C39: Tue | D39: 44894 | E39: 0.91666667 | G39: Wales | H39: 0 | I39: 3 | J39: England | M39: 1 | N39: 3 | O39: 1 | P39: 21.5 | Q39: 0 | R39: 2 | S39: 1 | T39: 19 | U39: 1 | V39: 3 | W39: 1 | X39: 21.5 | Y39: 1 | Z39: 1 | AA39: 0 | AB39: 24.5 | AC39: 1 | AD39: 2 | AE39: 1 | AF39: 23 | AG39: 1 | AH39: 1 | AI39: 0 | AJ39: 27 | AK39: 0 | AL39: 4 | AM39: 1 | AN39: 20
A40: 36 | B40: 3 | C40: Tue | D40: 44894 | E40: 0.91666667 | G40: Iran | H40: 0 | I40: 1 | J40: United States | M40: 1 | N40: 0 | O40: 0 | P40: 21.5 | Q40: 2 | R40: 1 | S40: 0 | T40: 19 | U40: 1 | V40: 2 | W40: 2 | X40: 23.5 | Y40: 1 | Z40: 1 | AA40: 0 | AB40: 24.5 | AC40: 2 | AD40: 1 | AE40: 0 | AF40: 23 | AG40: 2 | AH40: 3 | AI40: 2 | AJ40: 29 | AK40: 0 | AL40: 3 | AM40: 1 | AN40: 21
A41: 37 | B41: 3 | C41: Wed | D41: 44895 | E41: 0.75 | G41: Australia | H41: 1 | I41: 0 | J41: Denmark | M41: 0 | N41: 1 | O41: 0 | P41: 21.5 | Q41: 1 | R41: 2 | S41: 0 | T41: 19 | U41: 0 | V41: 2 | W41: 0 | X41: 23.5 | Y41: 1 | Z41: 2 | AA41: 0 | AB41: 24.5 | AC41: 0 | AD41: 2 | AE41: 0 | AF41: 23 | AG41: 1 | AH41: 1 | AI41: 0 | AJ41: 29 | AK41: 2 | AL41: 2 | AM41: 0 | AN41: 21
A42: 38 | B42: 3 | C42: Wed | D42: 44895 | E42: 0.75 | G42: Tunisia | H42: 1 | I42: 0 | J42: France | M42: 0 | N42: 2 | O42: 0 | P42: 21.5 | Q42: 0 | R42: 2 | S42: 0 | T42: 19 | U42: 1 | V42: 4 | W42: 0 | X42: 23.5 | Y42: 1 | Z42: 2 | AA42: 0 | AB42: 24.5 | AC42: 1 | AD42: 3 | AE42: 0 | AF42: 23 | AG42: 2 | AH42: 2 | AI42: 0 | AJ42: 29 | AK42: 1 | AL42: 3 | AM42: 0 | AN42: 21
A43: 39 | B43: 3 | C43: Wed | D43: 44895 | E43: 0.91666667 | G43: Poland | H43: 0 | I43: 2 | J43: Argentina | M43: 1 | N43: 1 | O43: 0 | P43: 21.5 | Q43: 1 | R43: 0 | S43: 0 | T43: 19 | U43: 1 | V43: 2 | W43: 1 | X43: 24.5 | Y43: 1 | Z43: 2 | AA43: 1 | AB43: 25.5 | AC43: 1 | AD43: 1 | AE43: 0 | AF43: 23 | AG43: 1 | AH43: 3 | AI43: 2 | AJ43: 31 | AK43: 1 | AL43: 1 | AM43: 0 | AN43: 21
A44: 40 | B44: 3 | C44: Wed | D44: 44895 | E44: 0.91666667 | G44: Saudi Arabia | H44: 1 | I44: 2 | J44: Mexico | M44: 1 | N44: 0 | O44: 0 | P44: 21.5 | Q44: 1 | R44: 1 | S44: 0 | T44: 19 | U44: 2 | V44: 2 | W44: 0 | X44: 24.5 | Y44: 1 | Z44: 2 | AA44: 3 | AB44: 28.5 | AC44: 1 | AD44: 0 | AE44: 0 | AF44: 23 | AG44: 1 | AH44: 2 | AI44: 3 | AJ44: 34 | AK44: 1 | AL44: 2 | AM44: 3 | AN44: 24
A45: 41 | B45: 3 | C45: Thu | D45: 44896 | E45: 0.75 | G45: Croatia | H45: 0 | I45: 0 | J45: Belgium | M45: 2 | N45: 0 | O45: 0 | P45: 21.5 | Q45: 1 | R45: 2 | S45: 0 | T45: 19 | U45: 2 | V45: 1 | W45: 0 | X45: 24.5 | Y45: 2 | Z45: 2 | AA45: 1.5 | AB45: 30 | AC45: 2 | AD45: 1 | AE45: 0 | AF45: 23 | AG45: 1 | AH45: 3 | AI45: 0 | AJ45: 34 | AK45: 1 | AL45: 1 | AM45: 1.5 | AN45: 25.5
A46: 42 | B46: 3 | C46: Thu | D46: 44896 | E46: 0.75 | G46: Canada | H46: 1 | I46: 2 | J46: Morocco | M46: 1 | N46: 0 | O46: 0 | P46: 21.5 | Q46: 0 | R46: 2 | S46: 1 | T46: 20 | U46: 0 | V46: 1 | W46: 2 | X46: 26.5 | Y46: 0 | Z46: 2 | AA46: 1 | AB46: 31 | AC46: 1 | AD46: 2 | AE46: 3 | AF46: 26 | AG46: 2 | AH46: 1 | AI46: 0 | AJ46: 34 | AK46: 1 | AL46: 2 | AM46: 3 | AN46: 28.5
...

Sheet Pins
A1: Martin | B1: 2648
A2: Ago | B2: 7803
A3: Daniel | B3: 6641
A4: Sonia | B4: 8934
A5: Anthony | B5: 2269
A6: Paulo | B6: 6025
A7: Selwyn | B7: 5589
A8: Donovan | B8: 2279

Sheet Group A
B1: Team | C1: P | D1: W | E1: D | F1: L | G1: GF | H1: GA | I1: GD | J1: Pts | K1: Rank | L1: Pts Standings
A2: 1 | B2: Qatar | C2: 2 | D2: 0 | E2: 0 | F2: 2 | G2: 1 | H2: 5 | I2: =G2-H2 -> -4 | J2: =(D2*3)+(E2*1) -> 0 | K2: =RANK(J2, $J$2:$J$5)+(COUNTIFS(J:J,J2,I:I,"<="&I2)-1)+COUNTIFS(J:J,J2,I:I,"<="&I2, A:A,"<="&A2)-2 -> 3 | L2: {=INDEX($B$2:$B$5, MATCH(1, $K$2:$K$5, 0))} -> Ecuador
A3: 2 | B3: Ecuador | C3: 2 | D3: 1 | E3: 1 | F3: 0 | G3: 3 | H3: 1 | I3: =G3-H3 -> 2 | J3: =(D3*3)+(E3*1) -> 4 | K3: =RANK(J3, $J$2:$J$5)+(COUNTIFS(J:J,J3,I:I,"<="&I3)-1)+COUNTIFS(J:J,J3,I:I,"<="&I3, A:A,"<="&A3)-2 -> 1 | L3: {=INDEX($B$2:$B$5, MATCH(2, $K$2:$K$5, 0))} -> Senegal
A4: 3 | B4: Senegal | C4: 2 | D4: 1 | E4: 0 | F4: 1 | G4: 3 | H4: 3 | I4: =G4-H4 -> 0 | J4: =(D4*3)+(E4*1) -> 3 | K4: =RANK(J4, $J$2:$J$5)+(COUNTIFS(J:J,J4,I:I,"<="&I4)-1)+COUNTIFS(J:J,J4,I:I,"<="&I4, A:A,"<="&A4)-2 -> 2 | L4: {=INDEX($B$2:$B$5, MATCH(3, $K$2:$K$5, 0))} -> Qatar
A5: 4 | B5: Netherlands | C5: 2 | D5: 1 | E5: 1 | F5: 0 | G5: 3 | H5: 1 | I5: =G5-H5 -> 2 | J5: =(D5*3)+(E5*1) -> 4 | K5: =RANK(J5, $J$2:$J$5)+(COUNTIFS(J:J,J5,I:I,"<="&I5)-1)+COUNTIFS(J:J,J5,I:I,"<="&I5, A:A,"<="&A5)-2 -> 2 | L5: {=INDEX($B$2:$B$5, MATCH(4, $K$2:$K$5, 0))} -> #N/A

Sheet Group B
B1: Team | C1: P | D1: W | E1: D | F1: L | G1: GF | H1: GA | I1: GD | J1: Pts | K1: Rank | L1: Pts Standings
A2: 1 | B2: England | C2: 2 | D2: 1 | E2: 1 | F2: 0 | G2: 6 | H2: 2 | I2: =G2-H2 -> 4 | J2: =(D2*3)+(E2*1) -> 4 | K2: =RANK(J2, $J$2:$J$5)+(COUNTIFS(J:J,J2,I:I,"<="&I2))+COUNTIFS(J:J,J2,I:I,"<="&I2, A:A,"<="&A2)-2 -> 1 | L2: {=INDEX($B$2:$B$5, MATCH(1, $K$2:$K$5, 0))} -> England
A3: 2 | B3: IR Iran | C3: 2 | D3: 1 | E3: 0 | F3: 1 | G3: 4 | H3: 6 | I3: =G3-H3 -> -2 | J3: =(D3*3)+(E3*1) -> 3 | K3: =RANK(J3, $J$2:$J$5)+(COUNTIFS(J:J,J3,I:I,"<="&I3))+COUNTIFS(J:J,J3,I:I,"<="&I3, A:A,"<="&A3)-2 -> 2 | L3: {=INDEX($B$2:$B$5, MATCH(2, $K$2:$K$5, 0))} -> IR Iran
A4: 3 | B4: USA | C4: 2 | D4: 0 | E4: 2 | F4: 0 | G4: 1 | H4: 1 | I4: =G4-H4 -> 0 | J4: =(D4*3)+(E4*1) -> 2 | K4: =RANK(J4, $J$2:$J$5)+(COUNTIFS(J:J,J4,I:I,"<="&I4))+COUNTIFS(J:J,J4,I:I,"<="&I4, A:A,"<="&A4)-2 -> 3 | L4: {=INDEX($B$2:$B$5, MATCH(3, $K$2:$K$5, 0))} -> USA
A5: 4 | B5: Wales | C5: 2 | D5: 0 | E5: 1 | F5: 1 | G5: 1 | H5: 3 | I5: =G5-H5 -> -2 | J5: =(D5*3)+(E5*1) -> 1 | K5: =RANK(J5, $J$2:$J$5)+(COUNTIFS(J:J,J5,I:I,"<="&I5))+COUNTIFS(J:J,J5,I:I,"<="&I5, A:A,"<="&A5)-2 -> 4 | L5: {=INDEX($B$2:$B$5, MATCH(4, $K$2:$K$5, 0))} -> Wales

Sheet Group C
B1: Team | C1: P | D1: W | E1: D | F1: L | G1: GF | H1: GA | I1: GD | J1: Pts | K1: Rank | L1: Pts Standings
A2: 1 | B2: Argentina | C2: 2 | D2: 1 | E2: 0 | F2: 1 | G2: 3 | H2: 2 | I2: =G2-H2 -> 1 | J2: =(D2*3)+(E2*1) -> 3 | K2: =RANK(J2, $J$2:$J$5)+SUMPRODUCT(--(J2=$J$2:$J$5),--(I2<$I$2:$I$5)) -> 2 | L2: {=INDEX($B$2:$B$5, MATCH(1, $K$2:$K$5, 0))} -> Poland
A3: 2 | B3: Saudi Arabia | C3: 2 | D3: 1 | E3: 0 | F3: 1 | G3: 2 | H3: 3 | I3: =G3-H3 -> -1 | J3: =(D3*3)+(E3*1) -> 3 | K3: =RANK(J3, $J$2:$J$5)+SUMPRODUCT(--(J3=$J$2:$J$5),--(I3<$I$2:$I$5)) -> 3 | L3: {=INDEX($B$2:$B$5, MATCH(2, $K$2:$K$5, 0))} -> Argentina
A4: 3 | B4: Mexico | C4: 2 | D4: 0 | E4: 1 | F4: 1 | G4: 0 | H4: 2 | I4: =G4-H4 -> -2 | J4: =(D4*3)+(E4*1) -> 1 | K4: =RANK(J4, $J$2:$J$5)+SUMPRODUCT(--(J4=$J$2:$J$5),--(I4<$I$2:$I$5)) -> 4 | L4: {=INDEX($B$2:$B$5, MATCH(3, $K$2:$K$5, 0))} -> Saudi Arabia
A5: 4 | B5: Poland | C5: 2 | D5: 1 | E5: 1 | F5: 0 | G5: 2 | H5: 0 | I5: =G5-H5 -> 2 | J5: =(D5*3)+(E5*1) -> 4 | K5: =RANK(J5, $J$2:$J$5)+SUMPRODUCT(--(J5=$J$2:$J$5),--(I5<$I$2:$I$5)) -> 1 | L5: {=INDEX($B$2:$B$5, MATCH(4, $K$2:$K$5, 0))} -> Mexico

Sheet Group D
B1: Team | C1: P | D1: W | E1: D | F1: L | G1: GF | H1: GA | I1: GD | J1: Pts | K1: Rank | L1: Pts Standings
A2: 1 | B2: France | C2: 2 | D2: 2 | E2: 0 | F2: 0 | G2: 6 | H2: 2 | I2: =G2-H2 -> 4 | J2: =(D2*3)+(E2*1) -> 6 | K2: =RANK(J2, $J$2:$J$5)+SUMPRODUCT(--(J2=$J$2:$J$5),--(I2<$I$2:$I$5)) -> 1 | L2: {=INDEX($B$2:$B$5, MATCH(1, $K$2:$K$5, 0))} -> France
A3: 2 | B3: Australia | C3: 2 | D3: 1 | E3: 0 | F3: 1 | G3: 2 | H3: 4 | I3: =G3-H3 -> -2 | J3: =(D3*3)+(E3*1) -> 3 | K3: =RANK(J3, $J$2:$J$5)+SUMPRODUCT(--(J3=$J$2:$J$5),--(I3<$I$2:$I$5)) -> 2 | L3: {=INDEX($B$2:$B$5, MATCH(2, $K$2:$K$5, 0))} -> Australia
A4: 3 | B4: Denmark | C4: 2 | D4: 0 | E4: 1 | F4: 1 | G4: 1 | H4: 2 | I4: =G4-H4 -> -1 | J4: =(D4*3)+(E4*1) -> 1 | K4: =RANK(J4, $J$2:$J$5)+SUMPRODUCT(--(J4=$J$2:$J$5),--(I4<$I$2:$I$5)) -> 3 | L4: {=INDEX($B$2:$B$5, MATCH(3, $K$2:$K$5, 0))} -> Denmark
A5: 4 | B5: Tunisia | C5: 2 | D5: 0 | E5: 1 | F5: 1 | G5: 0 | H5: 1 | I5: =G5-H5 -> -1 | J5: =(D5*3)+(E5*1) -> 1 | K5: =RANK(J5, $J$2:$J$5)+SUMPRODUCT(--(J5=$J$2:$J$5),--(I5<$I$2:$I$5)) -> 3 | L5: {=INDEX($B$2:$B$5, MATCH(4, $K$2:$K$5, 0))} -> #N/A

Sheet Group F
B1: Team | C1: P | D1: W | E1: D | F1: L | G1: GF | H1: GA | I1: GD | J1: Pts | K1: Rank | L1: Pts Standings
A2: 1 | B2: Belgium | C2: 2 | D2: 1 | E2: 0 | F2: 1 | G2: 1 | H2: 2 | I2: =G2-H2 -> -1 | J2: =(D2*3)+(E2*1) -> 3 | K2: =RANK(J2, $J$2:$J$5)+SUMPRODUCT(--(J2=$J$2:$J$5),--(I2<$I$2:$I$5)) -> 3 | L2: {=INDEX($B$2:$B$5, MATCH(1, $K$2:$K$5, 0))} -> Croatia
A3: 2 | B3: Canada | C3: 2 | D3: 0 | E3: 0 | F3: 2 | G3: 1 | H3: 5 | I3: =G3-H3 -> -4 | J3: =(D3*3)+(E3*1) -> 0 | K3: =RANK(J3, $J$2:$J$5)+SUMPRODUCT(--(J3=$J$2:$J$5),--(I3<$I$2:$I$5)) -> 4 | L3: {=INDEX($B$2:$B$5, MATCH(2, $K$2:$K$5, 0))} -> Morocco
A4: 3 | B4: Morocco | C4: 2 | D4: 1 | E4: 1 | F4: 0 | G4: 2 | H4: 0 | I4: =G4-H4 -> 2 | J4: =(D4*3)+(E4*1) -> 4 | K4: =RANK(J4, $J$2:$J$5)+SUMPRODUCT(--(J4=$J$2:$J$5),--(I4<$I$2:$I$5)) -> 2 | L4: {=INDEX($B$2:$B$5, MATCH(3, $K$2:$K$5, 0))} -> Belgium
A5: 4 | B5: Croatia | C5: 2 | D5: 1 | E5: 1 | F5: 0 | G5: 4 | H5: 1 | I5: =G5-H5 -> 3 | J5: =(D5*3)+(E5*1) -> 4 | K5: =RANK(J5, $J$2:$J$5)+SUMPRODUCT(--(J5=$J$2:$J$5),--(I5<$I$2:$I$5)) -> 1 | L5: {=INDEX($B$2:$B$5, MATCH(4, $K$2:$K$5, 0))} -> Canada

Sheet Group E
B1: Team | C1: P | D1: W | E1: D | F1: L | G1: GF | H1: GA | I1: GD | J1: Pts | K1: Rank | L1: Pts Standings
A2: 1 | B2: Spain | C2: 2 | D2: 1 | E2: 1 | F2: 0 | G2: 8 | H2: 1 | I2: =G2-H2 -> 7 | J2: =(D2*3)+(E2*1) -> 4 | K2: =RANK(J2, $J$2:$J$5)+SUMPRODUCT(--(J2=$J$2:$J$5),--(I2<$I$2:$I$5)) -> 1 | L2: {=INDEX($B$2:$B$5, MATCH(1, $K$2:$K$5, 0))} -> Spain
A3: 2 | B3: Costa Rica | C3: 2 | D3: 1 | E3: 0 | F3: 1 | G3: 1 | H3: 7 | I3: =G3-H3 -> -6 | J3: =(D3*3)+(E3*1) -> 3 | K3: =RANK(J3, $J$2:$J$5)+SUMPRODUCT(--(J3=$J$2:$J$5),--(I3<$I$2:$I$5)) -> 3 | L3: {=INDEX($B$2:$B$5, MATCH(2, $K$2:$K$5, 0))} -> Japan
A4: 3 | B4: Germany | C4: 2 | D4: 0 | E4: 1 | F4: 1 | G4: 2 | H4: 3 | I4: =G4-H4 -> -1 | J4: =(D4*3)+(E4*1) -> 1 | K4: =RANK(J4, $J$2:$J$5)+SUMPRODUCT(--(J4=$J$2:$J$5),--(I4<$I$2:$I$5)) -> 4 | L4: {=INDEX($B$2:$B$5, MATCH(3, $K$2:$K$5, 0))} -> Costa Rica
A5: 4 | B5: Japan | C5: 2 | D5: 1 | E5: 0 | F5: 1 | G5: 2 | H5: 2 | I5: =G5-H5 -> 0 | J5: =(D5*3)+(E5*1) -> 3 | K5: =RANK(J5, $J$2:$J$5)+SUMPRODUCT(--(J5=$J$2:$J$5),--(I5<$I$2:$I$5)) -> 2 | L5: {=INDEX($B$2:$B$5, MATCH(4, $K$2:$K$5, 0))} -> Germany

Sheet Group G
B1: Team | C1: P | D1: W | E1: D | F1: L | G1: GF | H1: GA | I1: GD | J1: Pts | K1: Rank | L1: Pts Standings
A2: 1 | B2: Brazil | C2: 1 | D2: 1 | E2: 0 | F2: 0 | G2: 2 | H2: 0 | I2: =G2-H2 -> 2 | J2: =(D2*3)+(E2*1) -> 3 | K2: =RANK(J2, $J$2:$J$5)+SUMPRODUCT(--(J2=$J$2:$J$5),--(I2<$I$2:$I$5)) -> 1 | L2: {=INDEX($B$2:$B$5, MATCH(1, $K$2:$K$5, 0))} -> Brazil
A3: 2 | B3: Serbia | C3: 2 | D3: 0 | E3: 1 | F3: 1 | G3: 3 | H3: 5 | I3: =G3-H3 -> -2 | J3: =(D3*3)+(E3*1) -> 1 | K3: =RANK(J3, $J$2:$J$5)+SUMPRODUCT(--(J3=$J$2:$J$5),--(I3<$I$2:$I$5)) -> 4 | L3: {=INDEX($B$2:$B$5, MATCH(2, $K$2:$K$5, 0))} -> Switzerland
A4: 3 | B4: Switzerland | C4: 1 | D4: 1 | E4: 0 | F4: 0 | G4: 1 | H4: 0 | I4: =G4-H4 -> 1 | J4: =(D4*3)+(E4*1) -> 3 | K4: =RANK(J4, $J$2:$J$5)+SUMPRODUCT(--(J4=$J$2:$J$5),--(I4<$I$2:$I$5)) -> 2 | L4: {=INDEX($B$2:$B$5, MATCH(3, $K$2:$K$5, 0))} -> Cameroon
A5: 4 | B5: Cameroon | C5: 2 | D5: 0 | E5: 1 | F5: 1 | G5: 3 | H5: 4 | I5: =G5-H5 -> -1 | J5: =(D5*3)+(E5*1) -> 1 | K5: =RANK(J5, $J$2:$J$5)+SUMPRODUCT(--(J5=$J$2:$J$5),--(I5<$I$2:$I$5)) -> 3 | L5: {=INDEX($B$2:$B$5, MATCH(4, $K$2:$K$5, 0))} -> Serbia

Sheet Group H
B1: Team | C1: P | D1: W | E1: D | F1: L | G1: GF | H1: GA | I1: GD | J1: Pts | K1: Rank | L1: Pts Standings
A2: 1 | B2: Portugal | C2: 2 | D2: 2 | E2: 0 | F2: 0 | G2: 5 | H2: 2 | I2: =G2-H2 -> 3 | J2: =(D2*3)+(E2*1) -> 6 | K2: =RANK(J2, $J$2:$J$5)+SUMPRODUCT(--(J2=$J$2:$J$5),--(I2<$I$2:$I$5)) -> 1 | L2: {=INDEX($B$2:$B$5, MATCH(1, $K$2:$K$5, 0))} -> Portugal
A3: 2 | B3: Ghana | C3: 2 | D3: 1 | E3: 0 | F3: 1 | G3: 5 | H3: 5 | I3: =G3-H3 -> 0 | J3: =(D3*3)+(E3*1) -> 3 | K3: =RANK(J3, $J$2:$J$5)+SUMPRODUCT(--(J3=$J$2:$J$5),--(I3<$I$2:$I$5)) -> 2 | L3: {=INDEX($B$2:$B$5, MATCH(2, $K$2:$K$5, 0))} -> Ghana
A4: 3 | B4: Uruguay | C4: 2 | D4: 0 | E4: 1 | F4: 1 | G4: 0 | H4: 2 | I4: =G4-H4 -> -2 | J4: =(D4*3)+(E4*1) -> 1 | K4: =RANK(J4, $J$2:$J$5)+SUMPRODUCT(--(J4=$J$2:$J$5),--(I4<$I$2:$I$5)) -> 4 | L4: {=INDEX($B$2:$B$5, MATCH(3, $K$2:$K$5, 0))} -> Korea Republic
A5: 4 | B5: Korea Republic | C5: 2 | D5: 0 | E5: 1 | F5: 1 | G5: 2 | H5: 3 | I5: =G5-H5 -> -1 | J5: =(D5*3)+(E5*1) -> 1 | K5: =RANK(J5, $J$2:$J$5)+SUMPRODUCT(--(J5=$J$2:$J$5),--(I5<$I$2:$I$5)) -> 3 | L5: {=INDEX($B$2:$B$5, MATCH(4, $K$2:$K$5, 0))} -> Uruguay

Sheet Teams
A1: Argentina
A2: Australia
A3: Belgium
A4: Brazil
A5: Cameroon
A6: Canada
A7: Costa Rica
A8: Croatia
A9: Denmark
A10: Ecuador
A11: England
A12: France
... A32: Wales
